Workbook
Name Slicer_STATUS: #N/A

Sheet Auto Sales data
A1: ORDERNUMBER | B1: ORDER QUANTITY | C1: PRICE EACH | D1: ORDERLINE NUMBER | E1: SALES | F1: ORDERDATE | G1: MONTH | H1: DAYS_SINCE_LASTORDER | I1: STATUS | J1: PRODUCTLINE | K1: MSRP | L1: PRODUCTCODE | M1: Column1 | N1: PHONE NUMBER | O1: ADDRESSLINE1 | P1: CITY | Q1: POSTAL CODE | R1: COUNTRY | S1: FULL NAME | T1: DEALSIZE | U1: PROFIT | V1: % PROFIT
A2: 10107 | B2: 30 | C2: 95.7 | D2: 2 | E2: 2871 | F2: 43155 | G2: February | H2: 28months | I2: Shipped | J2: Motorcycles | K2: 95 | L2: S10_1678 | N2: 2125557818 | O2: 897 Long Airport Avenue | P2: NYC | Q2: 10022 | R2: USA | S2: Yu Kwai | T2: Small | U2: =Auto[[#This Row],[SALES]]-(Auto[[#This Row],[MSRP]]*Auto[[#This Row],[ORDER QUANTITY]]) -> 21 | V2: =Auto[[#This Row],[PROFIT]]/100 -> 0.21
A3: 10121 | B3: 34 | C3: 81.35 | D3: 5 | E3: 2765.9 | F3: 43227 | G3: May | H3: 25months | I3: Shipped | J3: Motorcycles | K3: 95 | L3: S10_1678 | N3: 26.47.1555 | O3: 59 rue de l'Abbaye | P3: Reims | Q3: 51100 | R3: France | S3: Henriot Paul | T3: Small | U3: =Auto[[#This Row],[SALES]]-(Auto[[#This Row],[MSRP]]*Auto[[#This Row],[ORDER QUANTITY]]) -> -464.1 | V3: =Auto[[#This Row],[PROFIT]]/100 -> -4.641
A4: 10134 | B4: 41 | C4: 94.74 | D4: 2 | E4: 3884.34 | F4: 43282 | G4: July | H4: 23months | I4: Shipped | J4: Motorcycles | K4: 95 | L4: S10_1678 | N4: +33 1 46 62 7555 | O4: 27 rue du Colonel Pierre Avia | P4: Paris | Q4: 75508 | R4: France | S4: Da Cunha Daniel | T4: Medium | U4: =Auto[[#This Row],[SALES]]-(Auto[[#This Row],[MSRP]]*Auto[[#This Row],[ORDER QUANTITY]]) -> -10.66 | V4: =Auto[[#This Row],[PROFIT]]/100 -> -0.1066
A5: 10145 | B5: 45 | C5: 83.26 | D5: 6 | E5: 3746.7 | F5: 43337 | G5: August | H5: 22months | I5: Shipped | J5: Motorcycles | K5: 95 | L5: S10_1678 | N5: 6265557265 | O5: 78934 Hillside Dr. | P5: Pasadena | Q5: 90003 | R5: USA | S5: Young Julie | T5: Medium | U5: =Auto[[#This Row],[SALES]]-(Auto[[#This Row],[MSRP]]*Auto[[#This Row],[ORDER QUANTITY]]) -> -528.3 | V5: =Auto[[#This Row],[PROFIT]]/100 -> -5.283
A6: 10168 | B6: 36 | C6: 96.66 | D6: 1 | E6: 3479.76 | F6: 43401 | G6: October | H6: 20months | I6: Shipped | J6: Motorcycles | K6: 95 | L6: S10_1678 | N6: 6505556809 | O6: 9408 Furth Circle | P6: Burlingame | Q6: 94217 | R6: USA | S6: Hirano Juri | T6: Medium | U6: =Auto[[#This Row],[SALES]]-(Auto[[#This Row],[MSRP]]*Auto[[#This Row],[ORDER QUANTITY]]) -> 59.76 | V6: =Auto[[#This Row],[PROFIT]]/100 -> 0.5976
A7: 10180 | B7: 29 | C7: 86.13 | D7: 9 | E7: 2497.77 | F7: 43415 | G7: November | H7: 19months | I7: Shipped | J7: Motorcycles | K7: 95 | L7: S10_1678 | N7: 20.16.1555 | O7: 184, chausse de Tournai | P7: Lille | Q7: 59000 | R7: France | S7: Rance Martine | T7: Small | U7: =Auto[[#This Row],[SALES]]-(Auto[[#This Row],[MSRP]]*Auto[[#This Row],[ORDER QUANTITY]]) -> -257.23 | V7: =Auto[[#This Row],[PROFIT]]/100 -> -2.5723
A8: 10188 | B8: 48 | C8: 114.84 | D8: 1 | E8: 5512.32 | F8: 43422 | G8: November | H8: 19months | I8: Shipped | J8: Motorcycles | K8: 95 | L8: S10_1678 | N8: +47 2267 3215 | O8: Drammen 121, PR 744 Sentrum | P8: Bergen | Q8: N 5804 | R8: Norway | S8: Oeztan Veysel | T8: Medium | U8: =Auto[[#This Row],[SALES]]-(Auto[[#This Row],[MSRP]]*Auto[[#This Row],[ORDER QUANTITY]]) -> 952.32 | V8: =Auto[[#This Row],[PROFIT]]/100 -> 9.5232
A9: 10211 | B9: 41 | C9: 114.84 | D9: 14 | E9: 4708.44 | F9: 43480 | G9: January | H9: 17months | I9: Shipped | J9: Motorcycles | K9: 95 | L9: S10_1678 | N9: (1) 47.55.6555 | O9: 25, rue Lauriston | P9: Paris | Q9: 75016 | R9: France | S9: Perrier Dominique | T9: Medium | U9: =Auto[[#This Row],[SALES]]-(Auto[[#This Row],[MSRP]]*Auto[[#This Row],[ORDER QUANTITY]]) -> 813.44 | V9: =Auto[[#This Row],[PROFIT]]/100 -> 8.1344
A10: 10223 | B10: 37 | C10: 107.18 | D10: 1 | E10: 3965.66 | F10: 43516 | G10: February | H10: 16months | I10: Shipped | J10: Motorcycles | K10: 95 | L10: S10_1678 | N10: 03 9520 4555 | O10: 636 St Kilda Road | P10: Melbourne | Q10: 3004 | R10: Australia | S10: Ferguson Peter | T10: Medium | U10: =Auto[[#This Row],[SALES]]-(Auto[[#This Row],[MSRP]]*Auto[[#This Row],[ORDER QUANTITY]]) -> 450.66 | V10: =Auto[[#This Row],[PROFIT]]/100 -> 4.5066
A11: 10237 | B11: 23 | C11: 101.44 | D11: 7 | E11: 2333.12 | F11: 43560 | G11: April | H11: 14months | I11: Shipped | J11: Motorcycles | K11: 95 | L11: S10_1678 | N11: 2125551500 | O11: 2678 Kingston Rd. | P11: NYC | Q11: 10022 | R11: USA | S11: Frick Michael | T11: Small | U11: =Auto[[#This Row],[SALES]]-(Auto[[#This Row],[MSRP]]*Auto[[#This Row],[ORDER QUANTITY]]) -> 148.12 | V11: =Auto[[#This Row],[PROFIT]]/100 -> 1.4812
A12: 10251 | B12: 28 | C12: 113.88 | D12: 2 | E12: 3188.64 | F12: 43603 | G12: May | H12: 13months | I12: Shipped | J12: Motorcycles | K12: 95 | L12: S10_1678 | N12: 2015559350 | O12: 7476 Moss Rd. | P12: Newark | Q12: 94019 | R12: USA | S12: Brown William | T12: Medium | U12: =Auto[[#This Row],[SALES]]-(Auto[[#This Row],[MSRP]]*Auto[[#This Row],[ORDER QUANTITY]]) -> 528.64 | V12: =Auto[[#This Row],[PROFIT]]/100 -> 5.2864
A13: 10263 | B13: 34 | C13: 108.14 | D13: 2 | E13: 3676.76 | F13: 43644 | G13: June | H13: 12months | I13: Shipped | J13: Motorcycles | K13: 95 | L13: S10_1678 | N13: 2035552570 | O13: 25593 South Bay Ln. | P13: Bridgewater | Q13: 97562 | R13: USA | S13: King Julie | T13: Medium | U13: =Auto[[#This Row],[SALES]]-(Auto[[#This Row],[MSRP]]*Auto[[#This Row],[ORDER QUANTITY]]) -> 446.76 | V13: =Auto[[#This Row],[PROFIT]]/100 -> 4.4676
A14: 10275 | B14: 45 | C14: 92.83 | D14: 1 | E14: 4177.35 | F14: 43669 | G14: July | H14: 11months | I14: Shipped | J14: Motorcycles | K14: 95 | L14: S10_1678 | N14: 40.67.8555 | O14: 67, rue des Cinquante Otages | P14: Nantes | Q14: 44000 | R14: France | S14: Labrune Janine | T14: Medium | U14: =Auto[[#This Row],[SALES]]-(Auto[[#This Row],[MSRP]]*Auto[[#This Row],[ORDER QUANTITY]]) -> -97.65 | V14: =Auto[[#This Row],[PROFIT]]/100 -> -0.9765
A15: 10285 | B15: 36 | C15: 113.88 | D15: 6 | E15: 4099.68 | F15: 43704 | G15: August | H15: 10months | I15: Shipped | J15: Motorcycles | K15: 95 | L15: S10_1678 | N15: 6175558555 | O15: 39323 Spinnaker Dr. | P15: Cambridge | Q15: 51247 | R15: USA | S15: Hernandez Marta | T15: Medium | U15: =Auto[[#This Row],[SALES]]-(Auto[[#This Row],[MSRP]]*Auto[[#This Row],[ORDER QUANTITY]]) -> 679.68 | V15: =Auto[[#This Row],[PROFIT]]/100 -> 6.7968
A16: 10299 | B16: 23 | C16: 112.93 | D16: 9 | E16: 2597.39 | F16: 43738 | G16: September | H16: 9months | I16: Shipped | J16: Motorcycles | K16: 95 | L16: S10_1678 | N16: 90-224 8555 | O16: Keskuskatu 45 | P16: Helsinki | Q16: 21240 | R16: Finland | S16: Karttunen Matti | T16: Small | U16: =Auto[[#This Row],[SALES]]-(Auto[[#This Row],[MSRP]]*Auto[[#This Row],[ORDER QUANTITY]]) -> 412.39 | V16: =Auto[[#This Row],[PROFIT]]/100 -> 4.1239
A17: 10309 | B17: 41 | C17: 107.18 | D17: 5 | E17: 4394.38 | F17: 43753 | G17: October | H17: 8months | I17: Shipped | J17: Motorcycles | K17: 95 | L17: S10_1678 | N17: 07-98 9555 | O17: Erling Skakkes gate 78 | P17: Stavern | Q17: 4110 | R17: Norway | S17: Bergulfsen Jonas | T17: Medium | U17: =Auto[[#This Row],[SALES]]-(Auto[[#This Row],[MSRP]]*Auto[[#This Row],[ORDER QUANTITY]]) -> 499.38 | V17: =Auto[[#This Row],[PROFIT]]/100 -> 4.9938
A18: 10318 | B18: 46 | C18: 94.74 | D18: 1 | E18: 4358.04 | F18: 43771 | G18: November | H18: 8months | I18: Shipped | J18: Motorcycles | K18: 95 | L18: S10_1678 | N18: 2155551555 | O18: 7586 Pompton St. | P18: Allentown | Q18: 70267 | R18: USA | S18: Yu Kyung | T18: Medium | U18: =Auto[[#This Row],[SALES]]-(Auto[[#This Row],[MSRP]]*Auto[[#This Row],[ORDER QUANTITY]]) -> -11.96 | V18: =Auto[[#This Row],[PROFIT]]/100 -> -0.1196
A19: 10329 | B19: 42 | C19: 104.67 | D19: 1 | E19: 4396.14 | F19: 43784 | G19: November | H19: 7months | I19: Shipped | J19: Motorcycles | K19: 95 | L19: S10_1678 | N19: 2125557818 | O19: 897 Long Airport Avenue | P19: NYC | Q19: 10022 | R19: USA | S19: Yu Kwai | T19: Medium | U19: =Auto[[#This Row],[SALES]]-(Auto[[#This Row],[MSRP]]*Auto[[#This Row],[ORDER QUANTITY]]) -> 406.14 | V19: =Auto[[#This Row],[PROFIT]]/100 -> 4.0614
A20: 10341 | B20: 41 | C20: 188.73 | D20: 9 | E20: 7737.93 | F20: 43793 | G20: November | H20: 7months | I20: Shipped | J20: Motorcycles | K20: 95 | L20: S10_1678 | N20: 6562-9555 | O20: Geislweg 14 | P20: Salzburg | Q20: 5020 | R20: Austria | S20: Pipps Georg | T20: Large | U20: =Auto[[#This Row],[SALES]]-(Auto[[#This Row],[MSRP]]*Auto[[#This Row],[ORDER QUANTITY]]) -> 3842.93 | V20: =Auto[[#This Row],[PROFIT]]/100 -> 38.4293
A21: 10361 | B21: 20 | C21: 72.55 | D21: 13 | E21: 1451 | F21: 43816 | G21: December | H21: 6months | I21: Shipped | J21: Motorcycles | K21: 95 | L21: S10_1678 | N21: +61 2 9495 8555 | O21: Monitor Money Building, 815 Pacific Hwy | P21: Chatswood | Q21: 2067 | R21: Australia | S21: Huxley Adrian | T21: Small | U21: =Auto[[#This Row],[SALES]]-(Auto[[#This Row],[MSRP]]*Auto[[#This Row],[ORDER QUANTITY]]) -> -449 | V21: =Auto[[#This Row],[PROFIT]]/100 -> -4.49
A22: 10375 | B22: 21 | C22: 34.91 | D22: 12 | E22: 733.11 | F22: 43864 | G22: February | H22: 5months | I22: Shipped | J22: Motorcycles | K22: 95 | L22: S10_1678 | N22: 40.67.8555 | O22: 67, rue des Cinquante Otages | P22: Nantes | Q22: 44000 | R22: France | S22: Labrune Janine | T22: Small | U22: =Auto[[#This Row],[SALES]]-(Auto[[#This Row],[MSRP]]*Auto[[#This Row],[ORDER QUANTITY]]) -> -1261.89 | V22: =Auto[[#This Row],[PROFIT]]/100 -> -12.6189
A23: 10388 | B23: 42 | C23: 76.36 | D23: 4 | E23: 3207.12 | F23: 43893 | G23: March | H23: 4months | I23: Shipped | J23: Motorcycles | K23: 95 | L23: S10_1678 | N23: 5085552555 | O23: 1785 First Street | P23: New Bedford | Q23: 50553 | R23: USA | S23: Benitez Violeta | T23: Medium | U23: =Auto[[#This Row],[SALES]]-(Auto[[#This Row],[MSRP]]*Auto[[#This Row],[ORDER QUANTITY]]) -> -782.88 | V23: =Auto[[#This Row],[PROFIT]]/100 -> -7.8288
A24: 10403 | B24: 24 | C24: 101.44 | D24: 7 | E24: 2434.56 | F24: 43929 | G24: April | H24: 3months | I24: Shipped | J24: Motorcycles | K24: 95 | L24: S10_1678 | N24: (171) 555-2282 | O24: Berkeley Gardens 12 Brewery | P24: Liverpool | Q24: WX1 6LT | R24: UK | S24: Devon Elizabeth | T24: Small | U24: =Auto[[#This Row],[SALES]]-(Auto[[#This Row],[MSRP]]*Auto[[#This Row],[ORDER QUANTITY]]) -> 154.56 | V24: =Auto[[#This Row],[PROFIT]]/100 -> 1.5456
A25: 10417 | B25: 66 | C25: 113.88 | D25: 2 | E25: 7516.08 | F25: 43964 | G25: May | H25: 1months | I25: Disputed | J25: Motorcycles | K25: 95 | L25: S10_1678 | N25: (91) 555 94 44 | O25: C/ Moralzarzal, 86 | P25: Madrid | Q25: 28034 | R25: Spain | S25: Freyre Diego | T25: Large | U25: =Auto[[#This Row],[SALES]]-(Auto[[#This Row],[MSRP]]*Auto[[#This Row],[ORDER QUANTITY]]) -> 1246.08 | V25: =Auto[[#This Row],[PROFIT]]/100 -> 12.4608
A26: 10103 | B26: 26 | C26: 207.87 | D26: 11 | E26: 5404.62 | F26: 43129 | G26: January | H26: 29months | I26: Shipped | J26: Classic Cars | K26: 214 | L26: S10_1949 | N26: 07-98 9555 | O26: Erling Skakkes gate 78 | P26: Stavern | Q26: 4110 | R26: Norway | S26: Bergulfsen Jonas | T26: Medium | U26: =Auto[[#This Row],[SALES]]-(Auto[[#This Row],[MSRP]]*Auto[[#This Row],[ORDER QUANTITY]]) -> -159.38 | V26: =Auto[[#This Row],[PROFIT]]/100 -> -1.5938
A27: 10112 | B27: 29 | C27: 248.59 | D27: 1 | E27: 7209.11 | F27: 43183 | G27: March | H27: 28months | I27: Shipped | J27: Classic Cars | K27: 214 | L27: S10_1949 | N27: 0921-12 3555 | O27: BerguvsvÂ„gen 8 | P27: Lule | Q27: S-958 22 | R27: Sweden | S27: Berglund Christina | T27: Large | U27: =Auto[[#This Row],[SALES]]-(Auto[[#This Row],[MSRP]]*Auto[[#This Row],[ORDER QUANTITY]]) -> 1003.11 | V27: =Auto[[#This Row],[PROFIT]]/100 -> 10.0311
A28: 10126 | B28: 38 | C28: 192.87 | D28: 11 | E28: 7329.06 | F28: 43248 | G28: May | H28: 25months | I28: Shipped | J28: Classic Cars | K28: 214 | L28: S10_1949 | N28: (91) 555 22 82 | O28: C/ Araquil, 67 | P28: Madrid | Q28: 28023 | R28: Spain | S28: Sommer MartÂ¡n | T28: Large | U28: =Auto[[#This Row],[SALES]]-(Auto[[#This Row],[MSRP]]*Auto[[#This Row],[ORDER QUANTITY]]) -> -802.94 | V28: =Auto[[#This Row],[PROFIT]]/100 -> -8.0294
A29: 10140 | B29: 37 | C29: 199.3 | D29: 11 | E29: 7374.1 | F29: 43305 | G29: July | H29: 24months | I29: Shipped | J29: Classic Cars | K29: 214 | L29: S10_1949 | N29: 6505556809 | O29: 9408 Furth Circle | P29: Burlingame | Q29: 94217 | R29: USA | S29: Hirano Juri | T29: Large | U29: =Auto[[#This Row],[SALES]]-(Auto[[#This Row],[MSRP]]*Auto[[#This Row],[ORDER QUANTITY]]) -> -543.9 | V29: =Auto[[#This Row],[PROFIT]]/100 -> -5.439
A30: 10150 | B30: 45 | C30: 244.3 | D30: 8 | E30: 10993.5 | F30: 43362 | G30: September | H30: 22months | I30: Shipped | J30: Classic Cars | K30: 214 | L30: S10_1949 | N30: +65 221 7555 | O30: Bronz Sok., Bronz Apt. 3/6 Tesvikiye | P30: Singapore | Q30: 79903 | R30: Singapore | S30: Natividad Eric | T30: Large | U30: =Auto[[#This Row],[SALES]]-(Auto[[#This Row],[MSRP]]*Auto[[#This Row],[ORDER QUANTITY]]) -> 1363.5 | V30: =Auto[[#This Row],[PROFIT]]/100 -> 13.635
A31: 10163 | B31: 21 | C31: 231.44 | D31: 1 | E31: 4860.24 | F31: 43393 | G31: October | H31: 21months | I31: Shipped | J31: Classic Cars | K31: 214 | L31: S10_1949 | N31: 2125558493 | O31: 5905 Pompton St. | P31: NYC | Q31: 10022 | R31: USA | S31: Hernandez Maria | T31: Medium | U31: =Auto[[#This Row],[SALES]]-(Auto[[#This Row],[MSRP]]*Auto[[#This Row],[ORDER QUANTITY]]) -> 366.24 | V31: =Auto[[#This Row],[PROFIT]]/100 -> 3.6624
A32: 10174 | B32: 34 | C32: 235.73 | D32: 4 | E32: 8014.82 | F32: 43410 | G32: November | H32: 20months | I32: Shipped | J32: Classic Cars | K32: 214 | L32: S10_1949 | N32: 61-7-3844-6555 | O32: 31 Duncan St. West End | P32: South Brisbane | Q32: 4101 | R32: Australia | S32: Calaghan Tony | T32: Large | U32: =Auto[[#This Row],[SALES]]-(Auto[[#This Row],[MSRP]]*Auto[[#This Row],[ORDER QUANTITY]]) -> 738.82 | V32: =Auto[[#This Row],[PROFIT]]/100 -> 7.3882
A33: 10183 | B33: 23 | C33: 233.59 | D33: 8 | E33: 5372.57 | F33: 43417 | G33: November | H33: 20months | I33: Shipped | J33: Classic Cars | K33: 214 | L33: S10_1949 | N33: 2155554695 | O33: 782 First Street | P33: Philadelphia | Q33: 71270 | R33: USA | S33: Cervantes Francisca | T33: Medium | U33: =Auto[[#This Row],[SALES]]-(Auto[[#This Row],[MSRP]]*Auto[[#This Row],[ORDER QUANTITY]]) -> 450.57 | V33: =Auto[[#This Row],[PROFIT]]/100 -> 4.5057
A34: 10194 | B34: 42 | C34: 173.58 | D34: 11 | E34: 7290.36 | F34: 43429 | G34: November | H34: 20months | I34: Shipped | J34: Classic Cars | K34: 214 | L34: S10_1949 | N34: 78.32.5555 | O34: 2, rue du Commerce | P34: Lyon | Q34: 69004 | R34: France | S34: Saveley Mary | T34: Large | U34: =Auto[[#This Row],[SALES]]-(Auto[[#This Row],[MSRP]]*Auto[[#This Row],[ORDER QUANTITY]]) -> -1697.64 | V34: =Auto[[#This Row],[PROFIT]]/100 -> -16.9764
A35: 10206 | B35: 47 | C35: 192.87 | D35: 6 | E35: 9064.89 | F35: 43439 | G35: December | H35: 19months | I35: Shipped | J35: Classic Cars | K35: 214 | L35: S10_1949 | N35: (604) 555-3392 | O35: 1900 Oak St. | P35: Vancouver | Q35: V3F 2K1 | R35: Canada | S35: Tannamuri Yoshi | T35: Large | U35: =Auto[[#This Row],[SALES]]-(Auto[[#This Row],[MSRP]]*Auto[[#This Row],[ORDER QUANTITY]]) -> -993.11 | V35: =Auto[[#This Row],[PROFIT]]/100 -> -9.9311
A36: 10215 | B36: 35 | C36: 173.58 | D36: 3 | E36: 6075.3 | F36: 43494 | G36: January | H36: 17months | I36: Shipped | J36: Classic Cars | K36: 214 | L36: S10_1949 | N36: 3105553722 | O36: 3675 Furth Circle | P36: Burbank | Q36: 94019 | R36: USA | S36: Thompson Steve | T36: Medium | U36: =Auto[[#This Row],[SALES]]-(Auto[[#This Row],[MSRP]]*Auto[[#This Row],[ORDER QUANTITY]]) -> -1414.7 | V36: =Auto[[#This Row],[PROFIT]]/100 -> -14.147
A37: 10228 | B37: 29 | C37: 222.87 | D37: 2 | E37: 6463.23 | F37: 43534 | G37: March | H37: 16months | I37: Shipped | J37: Classic Cars | K37: 214 | L37: S10_1949 | N37: 6175555555 | O37: 4658 Baden Av. | P37: Cambridge | Q37: 51247 | R37: USA | S37: Tseng Kyung | T37: Medium | U37: =Auto[[#This Row],[SALES]]-(Auto[[#This Row],[MSRP]]*Auto[[#This Row],[ORDER QUANTITY]]) -> 257.23 | V37: =Auto[[#This Row],[PROFIT]]/100 -> 2.5723
A38: 10245 | B38: 34 | C38: 180.01 | D38: 9 | E38: 6120.34 | F38: 43589 | G38: May | H38: 14months | I38: Shipped | J38: Classic Cars | K38: 214 | L38: S10_1949 | N38: 2035559545 | O38: 567 North Pendale Street | P38: New Haven | Q38: 97823 | R38: USA | S38: Murphy Leslie | T38: Medium | U38: =Auto[[#This Row],[SALES]]-(Auto[[#This Row],[MSRP]]*Auto[[#This Row],[ORDER QUANTITY]]) -> -1155.66 | V38: =Auto[[#This Row],[PROFIT]]/100 -> -11.5566
A39: 10258 | B39: 32 | C39: 240.02 | D39: 6 | E39: 7680.64 | F39: 43631 | G39: June | H39: 13months | I39: Shipped | J39: Classic Cars | K39: 214 | L39: S10_1949 | N39: +81 3 3584 0555 | O39: 2-2-8 Roppongi | P39: Minato-ku | Q39: 106-0032 | R39: Japan | S39: Shimamura Akiko | T39: Large | U39: =Auto[[#This Row],[SALES]]-(Auto[[#This Row],[MSRP]]*Auto[[#This Row],[ORDER QUANTITY]]) -> 832.64 | V39: =Auto[[#This Row],[PROFIT]]/100 -> 8.3264
A40: 10270 | B40: 21 | C40: 233.59 | D40: 9 | E40: 4905.39 | F40: 43665 | G40: July | H40: 12months | I40: Shipped | J40: Classic Cars | K40: 214 | L40: S10_1949 | N40: +61 2 9495 8555 | O40: Monitor Money Building, 815 Pacific Hwy | P40: Chatswood | Q40: 2067 | R40: Australia | S40: Huxley Adrian | T40: Medium | U40: =Auto[[#This Row],[SALES]]-(Auto[[#This Row],[MSRP]]*Auto[[#This Row],[ORDER QUANTITY]]) -> 411.39 | V40: =Auto[[#This Row],[PROFIT]]/100 -> 4.1139
...

Sheet Pivot Analysis
Y1: COUNTRY | Z1: Denmark | BC1: USA
Y2: STATUS | Z2: Resolved | BC2: France
B3: Sum of SALES | D3: Months (ORDERDATE) | BC3: Norway | BD3: Shipped
B4: COUNTRY | C4: PRODUCTLINE | D4: Jan | E4: Feb | F4: Mar | G4: Apr | H4: May | I4: Jun | J4: Jul | K4: Aug | L4: Sep | M4: Oct | N4: Nov | O4: Dec | P4: Grand Total | T4: Row Labels | U4: Count of COUNTRY | V4: Sum of SALES | W4: Sum of % PROFIT | Y4: PRODUCTLINE | Z4: % PROFIT | AA4: DEALSIZE | AB4: SUM OF SALES | AC4: SUM OF PROFIT | BC4: Australia | BD4: Disputed
B5: Australia | C5: Classic Cars | D5: 3832 | F5: 4151.86 | H5: 23425.66 | J5: 25590.29 | L5: 52552.48 | N5: 83533.25 | P5: 193085.54 | T5: Classic Cars | U5: 949 | V5: 3842868.5 | W5: -1640.1546 | Y5: Motorcycles | Z5: =SUMIFS(Auto[% PROFIT], Auto[COUNTRY], $Z$1, Auto[PRODUCTLINE], Y5, Auto[STATUS], $Z$2) -> 0 | AA5: Small | AB5: =SUMIFS(Auto[SALES], Auto[COUNTRY], $Z$1, Auto[PRODUCTLINE], Y5) -> 0 | AC5: =SUMIFS(Auto[PROFIT], Auto[COUNTRY], $Z$1, Auto[PRODUCTLINE], Y5) -> 0 | BC5: Finland | BD5: In Process
B6: Australia | C6: Motorcycles | E6: 43380.46 | G6: 23475.59 | N6: 20331.81 | O6: 2780.9 | P6: 89968.76 | T6: Vintage Cars | U6: 579 | V6: 1806675.7 | W6: 792.7368 | Y6: Classic Cars | Z6: =SUMIFS(Auto[% PROFIT], Auto[COUNTRY], $Z$1, Auto[PRODUCTLINE], Y6, Auto[STATUS], $Z$2) -> 0 | AA6: Medium | AB6: =SUMIFS(Auto[SALES], Auto[COUNTRY], $Z$1, Auto[PRODUCTLINE], Y6) -> 157182.48 | AC6: =SUMIFS(Auto[PROFIT], Auto[COUNTRY], $Z$1, Auto[PRODUCTLINE], Y6) -> 459.48 | BC6: Austria | BD6: Cancelled
B7: Australia | C7: Planes | E7: 24769.68 | G7: 22347.02 | H7: 3843.84 | O7: 23893.33 | P7: 74853.87 | T7: Trucks and Buses | U7: 295 | V7: 1111559.2 | W7: 215.2319 | Y7: Trucks and Buses | Z7: =SUMIFS(Auto[% PROFIT], Auto[COUNTRY], $Z$1, Auto[PRODUCTLINE], Y7, Auto[STATUS], $Z$2) -> 0 | AA7: Large | AB7: =SUMIFS(Auto[SALES], Auto[COUNTRY], $Z$1, Auto[PRODUCTLINE], Y7) -> 9588.82 | AC7: =SUMIFS(Auto[PROFIT], Auto[COUNTRY], $Z$1, Auto[PRODUCTLINE], Y7) -> 1058.82 | BC7: UK | BD7: On Hold
B8: Australia | C8: Ships | H8: 3070.4 | O8: 1089.36 | P8: 4159.76 | T8: Motorcycles | U8: 313 | V8: 1103512.2 | W8: 263.7819 | Y8: Vintage Cars | Z8: =SUMIFS(Auto[% PROFIT], Auto[COUNTRY], $Z$1, Auto[PRODUCTLINE], Y8, Auto[STATUS], $Z$2) -> 0 | AB8: =SUMIFS(Auto[SALES], Auto[COUNTRY], $Z$1, Auto[PRODUCTLINE], Y8) -> 21105.81 | AC8: =SUMIFS(Auto[PROFIT], Auto[COUNTRY], $Z$1, Auto[PRODUCTLINE], Y8) -> -1200.19 | BC8: Spain | BD8: Resolved
B9: Australia | C9: Trains | L9: 1681.35 | P9: 1681.35 | T9: Planes | U9: 304 | V9: 969323.42 | W9: 225.2442 | Y9: Planes | Z9: =SUMIFS(Auto[% PROFIT], Auto[COUNTRY], $Z$1, Auto[PRODUCTLINE], Y9, Auto[STATUS], $Z$2) -> -1.1855 | AB9: =SUMIFS(Auto[SALES], Auto[COUNTRY], $Z$1, Auto[PRODUCTLINE], Y9) -> 7586.45 | AC9: =SUMIFS(Auto[PROFIT], Auto[COUNTRY], $Z$1, Auto[PRODUCTLINE], Y9) -> -118.55 | BC9: Sweden
B10: Australia | C10: Trucks and Buses | D10: 23290.17 | F10: 6626.7 | J10: 17715.31 | N10: 29686.32 | P10: 77318.5 | T10: Ships | U10: 230 | V10: 700039.22 | W10: 137.4322 | Y10: Ships | Z10: =SUMIFS(Auto[% PROFIT], Auto[COUNTRY], $Z$1, Auto[PRODUCTLINE], Y10, Auto[STATUS], $Z$2) -> 11.4916 | AB10: =SUMIFS(Auto[SALES], Auto[COUNTRY], $Z$1, Auto[PRODUCTLINE], Y10) -> 38697.26 | AC10: =SUMIFS(Auto[PROFIT], Auto[COUNTRY], $Z$1, Auto[PRODUCTLINE], Y10) -> 1270.26 | BC10: Singapore
B11: Australia | C11: Vintage Cars | D11: 2730 | E11: 3217.46 | F11: 24381.69 | G11: 4575.05 | H11: 37747.8 | J11: 38723.62 | L11: 3598.22 | N11: 64439.92 | O11: 10141.56 | P11: 189555.32 | T11: Trains | U11: 77 | V11: 226243.47 | W11: 291.9947 | Y11: Trains | Z11: =SUMIFS(Auto[% PROFIT], Auto[COUNTRY], $Z$1, Auto[PRODUCTLINE], Y11, Auto[STATUS], $Z$2) -> 0 | AB11: =SUMIFS(Auto[SALES], Auto[COUNTRY], $Z$1, Auto[PRODUCTLINE], Y11) -> 11476.33 | AC11: =SUMIFS(Auto[PROFIT], Auto[COUNTRY], $Z$1, Auto[PRODUCTLINE], Y11) -> 1002.33 | BC11: Canada
B12: Austria | C12: Classic Cars | G12: 5004.8 | H12: 59475.1 | M12: 6732.09 | N12: 30247.48 | P12: 101459.47 | T12: Grand Total | U12: 2747 | V12: 9760221.7 | W12: 286.2671 | BC12: Japan
B13: Austria | C13: Motorcycles | N13: 26047.66 | P13: 26047.66 | BC13: Italy
B14: Austria | C14: Planes | G14: 14216.32 | N14: 3644.12 | P14: 17860.44 | BC14: Denmark
B15: Austria | C15: Ships | G15: 9024.73 | P15: 9024.73 | BC15: Belgium
B16: Austria | C16: Trucks and Buses | M16: 20472.75 | P16: 20472.75 | BC16: Philippines
B17: Austria | C17: Vintage Cars | F17: 8775.16 | G17: 10383.29 | J17: 6693.28 | M17: 1345.75 | P17: 27197.48 | T17: COUNTRY | U17: SALES | Y17: PRODUCTLINE | Z17: TOTAL REVENUE | BC17: Germany
B18: Belgium | C18: Classic Cars | D18: 16628.16 | J18: 3508.8 | P18: 20136.96 | T18: USA | U18: =SUMIF('Auto Sales data'!R:R, T18,'Auto Sales data'!E:E) -> 3355575.7 | Y18: Classic Cars | Z18: =SUMIF('Auto Sales data'!J:J, Y18,'Auto Sales data'!E:E) -> 3842868.5 | BC18: Switzerland
B19: Belgium | C19: Planes | N19: 5624.79 | P19: 5624.79 | T19: Spain | U19: =SUMIF('Auto Sales data'!R:R, T19,'Auto Sales data'!E:E) -> 1215686.9 | Y19: Vintage Cars | Z19: =SUMIF('Auto Sales data'!J:J, Y19,'Auto Sales data'!E:E) -> 1806675.7 | BC19: Ireland
B20: Belgium | C20: Ships | E20: 9035.63 | J20: 20360.14 | N20: 2312.24 | P20: 31708.01 | T20: France | U20: =SUMIF('Auto Sales data'!R:R, T20,'Auto Sales data'!E:E) -> 1110916.5 | Y20: Trucks and Buses | Z20: =SUMIF('Auto Sales data'!J:J, Y20,'Auto Sales data'!E:E) -> 1111559.2
B21: Belgium | C21: Trains | E21: 1855.41 | G21: 1711.26 | J21: 5450.59 | P21: 9017.26 | T21: Australia | U21: =SUMIF('Auto Sales data'!R:R, T21,'Auto Sales data'!E:E) -> 630623.1 | Y21: Motorcycles | Z21: =SUMIF('Auto Sales data'!J:J, Y21,'Auto Sales data'!E:E) -> 1103512.2
B22: Belgium | C22: Vintage Cars | E22: 7909.05 | H22: 8411.95 | J22: 18440.95 | K22: 1637.2 | N22: 5526.45 | P22: 41925.6 | T22: UK | U22: =SUMIF('Auto Sales data'!R:R, T22,'Auto Sales data'!E:E) -> 478880.46 | Y22: Planes | Z22: =SUMIF('Auto Sales data'!J:J, Y22,'Auto Sales data'!E:E) -> 969323.42
B23: Canada | C23: Classic Cars | H23: 12144.76 | I23: 3378.24 | K23: 2992 | M23: 14224.15 | N23: 15947.29 | O23: 12936.78 | P23: 61623.22 | T23: Italy | U23: =SUMIF('Auto Sales data'!R:R, T23,'Auto Sales data'!E:E) -> 374674.31 | Y23: Ships | Z23: =SUMIF('Auto Sales data'!J:J, Y23,'Auto Sales data'!E:E) -> 700039.22
B24: Canada | C24: Motorcycles | G24: 4177.49 | P24: 4177.49 | T24: Finland | U24: =SUMIF('Auto Sales data'!R:R, T24,'Auto Sales data'!E:E) -> 329581.91 | Y24: Trains | Z24: =SUMIF('Auto Sales data'!J:J, Y24,'Auto Sales data'!E:E) -> 226243.47
B25: Canada | C25: Planes | G25: 23032.84 | K25: 2477.23 | P25: 25510.07 | T25: Norway | U25: =SUMIF('Auto Sales data'!R:R, T25,'Auto Sales data'!E:E) -> 307463.7
B26: Canada | C26: Ships | I26: 17389.95 | K26: 22919.06 | P26: 40309.01 | T26: Singapore | U26: =SUMIF('Auto Sales data'!R:R, T26,'Auto Sales data'!E:E) -> 288488.41
B27: Canada | C27: Trucks and Buses | H27: 19452.76 | M27: 22352.56 | O27: 10140.66 | P27: 51945.98 | T27: Denmark | U27: =SUMIF('Auto Sales data'!R:R, T27,'Auto Sales data'!E:E) -> 245637.15
B28: Canada | C28: Vintage Cars | G28: 4092.17 | H28: 2095.45 | I28: 3796.34 | K28: 14944.06 | O28: 15584.77 | P28: 40512.79 | T28: Canada | U28: =SUMIF('Auto Sales data'!R:R, T28,'Auto Sales data'!E:E) -> 224078.56
B29: Denmark | C29: Classic Cars | E29: 20464.41 | G29: 57342.43 | M29: 79375.64 | P29: 157182.48 | T29: Germany | U29: =SUMIF('Auto Sales data'!R:R, T29,'Auto Sales data'!E:E) -> 220472.09
B30: Denmark | C30: Planes | N30: 7586.45 | P30: 7586.45 | T30: Sweden | U30: =SUMIF('Auto Sales data'!R:R, T30,'Auto Sales data'!E:E) -> 210014.21
B31: Denmark | C31: Ships | E31: 20452.04 | M31: 1753.06 | N31: 16492.16 | P31: 38697.26 | T31: Austria | U31: =SUMIF('Auto Sales data'!R:R, T31,'Auto Sales data'!E:E) -> 202062.53
B32: Denmark | C32: Trains | E32: 4330.1 | M32: 7146.23 | P32: 11476.33 | T32: Japan | U32: =SUMIF('Auto Sales data'!R:R, T32,'Auto Sales data'!E:E) -> 188167.81
B33: Denmark | C33: Trucks and Buses | M33: 9588.82 | P33: 9588.82 | T33: Switzerland | U33: =SUMIF('Auto Sales data'!R:R, T33,'Auto Sales data'!E:E) -> 117713.56
B34: Denmark | C34: Vintage Cars | E34: 13624.56 | I34: 4749.45 | M34: 2731.8 | P34: 21105.81 | T34: Belgium | U34: =SUMIF('Auto Sales data'!R:R, T34,'Auto Sales data'!E:E) -> 108412.62
B35: Finland | C35: Classic Cars | D35: 39762.89 | E35: 26422.82 | G35: 17813.4 | H35: 25901.18 | K35: 16537.46 | L35: 22588.41 | M35: 4526.08 | P35: 153552.24 | T35: Philippines | U35: =SUMIF('Auto Sales data'!R:R, T35,'Auto Sales data'!E:E) -> 94015.73
B36: Finland | C36: Motorcycles | D36: 15656.85 | L36: 32209.87 | P36: 47866.72 | T36: Ireland | U36: =SUMIF('Auto Sales data'!R:R, T36,'Auto Sales data'!E:E) -> 57756.43
B37: Finland | C37: Planes | D37: 11262.27 | M37: 23112.86 | P37: 34375.13
B38: Finland | C38: Ships | D38: 23400.52 | M38: 6407.92 | P38: 29808.44
B39: Finland | C39: Trains | H39: 5117.05 | P39: 5117.05
B40: Finland | C40: Trucks and Buses | K40: 15031.97 | L40: 25447.36 | P40: 40479.33
...

Sheet Sheet2
B1: PRODUCTLINE | C1: CUSTOMERNAME | D1: STATUS | E1: DEALSIZE | F1: COUNTRY
B2: Motorcycles | C2: Land of Toys Inc. | D2: Shipped | E2: Small | F2: USA
B3: Classic Cars | C3: Reims Collectables | D3: Disputed | E3: Medium | F3: France
B4: Trucks and Buses | C4: Lyon Souveniers | D4: In Process | E4: Large | F4: Norway
B5: Vintage Cars | C5: Toys4GrownUps.com | D5: Cancelled | F5: Australia
B6: Planes | C6: Technics Stores Inc. | D6: On Hold | F6: Finland
B7: Ships | C7: Daedalus Designs Imports | D7: Resolved | F7: Austria
B8: Trains | C8: Herkku Gifts | F8: UK
C9: Auto Canal Petit | F9: Spain
C10: Australian Collectors, Co. | F10: Sweden
C11: Vitachrome Inc. | F11: Singapore
C12: Tekni Collectables Inc. | F12: Canada
C13: Gift Depot Inc. | F13: Japan
C14: La Rochelle Gifts | E14: DEALSIZE | F14: Italy
C15: Marta's Replicas Co. | E15: Small | F15: Denmark
C16: Toys of Finland, Co. | E16: Medium | F16: Belgium
C17: Baane Mini Imports | E17: Large | F17: Philippines
C18: Diecast Classics Inc. | F18: Germany
C19: Salzburg Collectables | F19: Switzerland
C20: Souveniers And Things Co. | F20: Ireland
C21: FunGiftIdeas.com
C22: UK Collectables, Ltd.
C23: Euro Shopping Channel
C24: Volvo Model Replicas, Co
C25: Corrida Auto Replicas, Ltd
C26: Dragon Souveniers, Ltd.
C27: Classic Legends Inc.
C28: Australian Gift Network, Co
C29: Classic Gift Ideas, Inc
C30: Saveley & Henriot, Co.
C31: Canadian Gift Exchange Network
C32: West Coast Collectables Co.
... C90: Auto-Moto Classics Inc.
